[2025-03-25T14:29:11.166+0000] {taskinstance.py:1157} INFO - Dependencies all met for dep_context=non-requeueable deps ti=<TaskInstance: frequent_flyers.create_schema scheduled__2025-03-24T02:00:00+00:00 [queued]>
[2025-03-25T14:29:11.179+0000] {taskinstance.py:1157} INFO - Dependencies all met for dep_context=requeueable deps ti=<TaskInstance: frequent_flyers.create_schema scheduled__2025-03-24T02:00:00+00:00 [queued]>
[2025-03-25T14:29:11.179+0000] {taskinstance.py:1359} INFO - Starting attempt 2 of 2
[2025-03-25T14:29:11.198+0000] {taskinstance.py:1380} INFO - Executing <Task(PostgresOperator): create_schema> on 2025-03-24 02:00:00+00:00
[2025-03-25T14:29:11.223+0000] {standard_task_runner.py:57} INFO - Started process 352 to run task
[2025-03-25T14:29:11.233+0000] {standard_task_runner.py:84} INFO - Running: ['***', 'tasks', 'run', 'frequent_flyers', 'create_schema', 'scheduled__2025-03-24T02:00:00+00:00', '--job-id', '4', '--raw', '--subdir', 'DAGS_FOLDER/frequent_flyers.py', '--cfg-path', '/tmp/tmpgft221h0']
[2025-03-25T14:29:11.240+0000] {standard_task_runner.py:85} INFO - Job 4: Subtask create_schema
[2025-03-25T14:29:11.315+0000] {logging_mixin.py:151} WARNING - /home/***/.local/lib/python3.8/site-packages/***/settings.py:195 DeprecationWarning: The sql_alchemy_conn option in [core] has been moved to the sql_alchemy_conn option in [database] - the old setting has been used, but please update your config.
[2025-03-25T14:29:11.456+0000] {task_command.py:415} INFO - Running <TaskInstance: frequent_flyers.create_schema scheduled__2025-03-24T02:00:00+00:00 [running]> on host 55005b7b65eb
[2025-03-25T14:29:11.687+0000] {taskinstance.py:1660} INFO - Exporting env vars: AIRFLOW_CTX_DAG_OWNER='***' AIRFLOW_CTX_DAG_ID='frequent_flyers' AIRFLOW_CTX_TASK_ID='create_schema' AIRFLOW_CTX_EXECUTION_DATE='2025-03-24T02:00:00+00:00' AIRFLOW_CTX_TRY_NUMBER='2' AIRFLOW_CTX_DAG_RUN_ID='scheduled__2025-03-24T02:00:00+00:00'
[2025-03-25T14:29:11.692+0000] {sql.py:274} INFO - Executing: 
CREATE SCHEMA IF NOT EXISTS presentation;
[2025-03-25T14:29:11.737+0000] {taskinstance.py:1935} ERROR - Task failed with exception
Traceback (most recent call last):
  File "/home/airflow/.local/lib/python3.8/site-packages/airflow/providers/common/sql/operators/sql.py", line 275, in execute
    hook = self.get_db_hook()
  File "/home/airflow/.local/lib/python3.8/site-packages/airflow/providers/common/sql/operators/sql.py", line 186, in get_db_hook
    return self._hook
  File "/usr/local/lib/python3.8/functools.py", line 967, in __get__
    val = self.func(instance)
  File "/home/airflow/.local/lib/python3.8/site-packages/airflow/providers/common/sql/operators/sql.py", line 148, in _hook
    conn = BaseHook.get_connection(conn_id)
  File "/home/airflow/.local/lib/python3.8/site-packages/airflow/hooks/base.py", line 72, in get_connection
    conn = Connection.get_connection_from_secrets(conn_id)
  File "/home/airflow/.local/lib/python3.8/site-packages/airflow/models/connection.py", line 477, in get_connection_from_secrets
    raise AirflowNotFoundException(f"The conn_id `{conn_id}` isn't defined")
airflow.exceptions.AirflowNotFoundException: The conn_id `postgres_dwh` isn't defined
[2025-03-25T14:29:11.746+0000] {taskinstance.py:1398} INFO - Marking task as FAILED. dag_id=frequent_flyers, task_id=create_schema, execution_date=20250324T020000, start_date=20250325T142911, end_date=20250325T142911
[2025-03-25T14:29:11.766+0000] {standard_task_runner.py:104} ERROR - Failed to execute job 4 for task create_schema (The conn_id `postgres_dwh` isn't defined; 352)
[2025-03-25T14:29:11.779+0000] {local_task_job_runner.py:228} INFO - Task exited with return code 1
[2025-03-25T14:29:11.819+0000] {taskinstance.py:2776} INFO - 0 downstream tasks scheduled from follow-on schedule check
