[2025-03-25T14:28:07.990+0000] {taskinstance.py:1157} INFO - Dependencies all met for dep_context=non-requeueable deps ti=<TaskInstance: passanger_traffic.creare1 manual__2025-03-25T14:28:00.556927+00:00 [queued]>
[2025-03-25T14:28:08.011+0000] {taskinstance.py:1157} INFO - Dependencies all met for dep_context=requeueable deps ti=<TaskInstance: passanger_traffic.creare1 manual__2025-03-25T14:28:00.556927+00:00 [queued]>
[2025-03-25T14:28:08.012+0000] {taskinstance.py:1359} INFO - Starting attempt 1 of 2
[2025-03-25T14:28:08.047+0000] {taskinstance.py:1380} INFO - Executing <Task(PostgresOperator): creare1> on 2025-03-25 14:28:00.556927+00:00
[2025-03-25T14:28:08.063+0000] {standard_task_runner.py:57} INFO - Started process 325 to run task
[2025-03-25T14:28:08.076+0000] {standard_task_runner.py:84} INFO - Running: ['***', 'tasks', 'run', 'passanger_traffic', 'creare1', 'manual__2025-03-25T14:28:00.556927+00:00', '--job-id', '2', '--raw', '--subdir', 'DAGS_FOLDER/passenger_traffic_dag.py', '--cfg-path', '/tmp/tmpji8_rw2s']
[2025-03-25T14:28:08.082+0000] {standard_task_runner.py:85} INFO - Job 2: Subtask creare1
[2025-03-25T14:28:08.193+0000] {logging_mixin.py:151} WARNING - /home/***/.local/lib/python3.8/site-packages/***/settings.py:195 DeprecationWarning: The sql_alchemy_conn option in [core] has been moved to the sql_alchemy_conn option in [database] - the old setting has been used, but please update your config.
[2025-03-25T14:28:08.513+0000] {task_command.py:415} INFO - Running <TaskInstance: passanger_traffic.creare1 manual__2025-03-25T14:28:00.556927+00:00 [running]> on host 55005b7b65eb
[2025-03-25T14:28:08.902+0000] {taskinstance.py:1660} INFO - Exporting env vars: AIRFLOW_CTX_DAG_OWNER='***' AIRFLOW_CTX_DAG_ID='passanger_traffic' AIRFLOW_CTX_TASK_ID='creare1' AIRFLOW_CTX_EXECUTION_DATE='2025-03-25T14:28:00.556927+00:00' AIRFLOW_CTX_TRY_NUMBER='1' AIRFLOW_CTX_DAG_RUN_ID='manual__2025-03-25T14:28:00.556927+00:00'
[2025-03-25T14:28:08.907+0000] {sql.py:274} INFO - Executing: 
    CREATE SCHEMA IF NOT EXISTS presentation;
[2025-03-25T14:28:08.967+0000] {taskinstance.py:1935} ERROR - Task failed with exception
Traceback (most recent call last):
  File "/home/airflow/.local/lib/python3.8/site-packages/airflow/providers/common/sql/operators/sql.py", line 275, in execute
    hook = self.get_db_hook()
  File "/home/airflow/.local/lib/python3.8/site-packages/airflow/providers/common/sql/operators/sql.py", line 186, in get_db_hook
    return self._hook
  File "/usr/local/lib/python3.8/functools.py", line 967, in __get__
    val = self.func(instance)
  File "/home/airflow/.local/lib/python3.8/site-packages/airflow/providers/common/sql/operators/sql.py", line 148, in _hook
    conn = BaseHook.get_connection(conn_id)
  File "/home/airflow/.local/lib/python3.8/site-packages/airflow/hooks/base.py", line 72, in get_connection
    conn = Connection.get_connection_from_secrets(conn_id)
  File "/home/airflow/.local/lib/python3.8/site-packages/airflow/models/connection.py", line 477, in get_connection_from_secrets
    raise AirflowNotFoundException(f"The conn_id `{conn_id}` isn't defined")
airflow.exceptions.AirflowNotFoundException: The conn_id `postgres_dwh` isn't defined
[2025-03-25T14:28:08.987+0000] {taskinstance.py:1398} INFO - Marking task as UP_FOR_RETRY. dag_id=passanger_traffic, task_id=creare1, execution_date=20250325T142800, start_date=20250325T142807, end_date=20250325T142808
[2025-03-25T14:28:09.023+0000] {standard_task_runner.py:104} ERROR - Failed to execute job 2 for task creare1 (The conn_id `postgres_dwh` isn't defined; 325)
[2025-03-25T14:28:09.076+0000] {local_task_job_runner.py:228} INFO - Task exited with return code 1
[2025-03-25T14:28:09.176+0000] {taskinstance.py:2776} INFO - 0 downstream tasks scheduled from follow-on schedule check
